<?xml version="1.0"?>
<robot xmlns:xacro="http://www.ros.org/wiki/xacro">

  <xacro:macro name="rover2_joints" params="prefix">

    <!-- Link definitions -->
    <link name="${prefix}base_link"/>
    <link name="${prefix}left_wheel"/>
    <link name="${prefix}right_wheel"/>

    <!-- Joint definitions -->
    <joint name="${prefix}left_wheel_joint" type="continuous">
      <parent link="${prefix}base_link"/>
      <child link="${prefix}left_wheel"/>
      <origin xyz="0.0 0.125 0.0" rpy="-1.5708 0 0"/>
      <axis xyz="0 0 1"/>
    </joint>

    <joint name="${prefix}right_wheel_joint" type="continuous">
      <parent link="${prefix}base_link"/>
      <child link="${prefix}right_wheel"/>
      <origin xyz="0.0 -0.125 0.0" rpy="-1.5708 0 0"/>
      <axis xyz="0 0 1"/>
    </joint>

  </xacro:macro>

</robot>
